{
  "modified": "2024-06-25T13:39:10Z",
  "published": "2024-06-25T13:39:10Z",
  "schema_version": "1.5.0",
  "id": "",
  "aliases": [
    "SNYK-PYTHON-PYCORDF-6513531"
  ],
  "affected": [
    {
      "package": {
        "ecosystem": "PyPI",
        "name": "py-cordf",
        "purl": "pkg:pypi/py-cordf"
      },
      "versions": [
        "1.0.0"
      ]
    }
  ],
  "references": [
    {
      "type": "ARTICLE",
      "url": "https://medium.com/checkmarx-security/pypi-is-under-attack-project-creation-and-user-registration-suspended-heres-the-details-c3b6291d4579"
    },
    {
      "type": "ADVISORY",
      "url": "https://security.snyk.io/vuln/SNYK-PYTHON-PYCORDF-6513531"
    }
  ],
  "credits": [
    {
      "name": "ReversingLabs",
      "type": "FINDER",
      "contact": [
        "https://www.reversinglabs.com"
      ]
    }
  ],
  "database_specific": {
    "malicious-packages-origins": [
      {
        "source": "reversing-labs",
        "sha256": "baf6db8c16538643f46258bd64f3c9a753e2b857523d65f8cc19bd96899af855",
        "import_time": "2024-06-28T02:49:54.246690751Z",
        "id": "RLMA-2024-04387",
        "modified_time": "2024-06-25T13:39:10Z",
        "versions": [
          "1.0.0"
        ]
      }
    ]
  }
}
