{
  "modified": "2024-10-16T14:45:27Z",
  "published": "2024-10-16T14:45:27Z",
  "schema_version": "1.5.0",
  "id": "",
  "aliases": [
    "MAL-2024-5478"
  ],
  "affected": [
    {
      "package": {
        "ecosystem": "PyPI",
        "name": "pilpow"
      }
    }
  ],
  "references": [
    {
      "type": "ADVISORY",
      "url": "https://github.com/ossf/malicious-packages/blob/main/osv/malicious/pypi/pilpow/MAL-2024-5478.json"
    }
  ],
  "database_specific": {
    "malicious-packages-origins": [
      {
        "source": "reversing-labs",
        "sha256": "b9139246721554c206525d65443563f5a8cb8c7b0cda6f2980affdb9ad8d0638",
        "import_time": "2024-10-24T00:59:35.37112242Z",
        "id": "RLUA-2024-08688",
        "modified_time": "2024-10-16T14:45:27Z"
      }
    ]
  }
}
