{
  "modified": "2024-06-25T13:41:55Z",
  "published": "2024-06-25T13:41:55Z",
  "schema_version": "1.5.0",
  "id": "",
  "aliases": [
    "SNYK-PYTHON-REQUNESTS-6513222"
  ],
  "affected": [
    {
      "package": {
        "ecosystem": "PyPI",
        "name": "requnests",
        "purl": "pkg:pypi/requnests"
      },
      "versions": [
        "1.0.0"
      ]
    }
  ],
  "references": [
    {
      "type": "ADVISORY",
      "url": "https://security.snyk.io/vuln/SNYK-PYTHON-REQUNESTS-6513222"
    },
    {
      "type": "ARTICLE",
      "url": "https://medium.com/checkmarx-security/pypi-is-under-attack-project-creation-and-user-registration-suspended-heres-the-details-c3b6291d4579"
    }
  ],
  "credits": [
    {
      "name": "ReversingLabs",
      "type": "FINDER",
      "contact": [
        "https://www.reversinglabs.com"
      ]
    }
  ],
  "database_specific": {
    "malicious-packages-origins": [
      {
        "source": "reversing-labs",
        "sha256": "21a9e2ff3738768ae1e72374ea88f64a9d8b4ae388643227ac8b16ac82d5a934",
        "import_time": "2024-06-28T02:50:34.895094044Z",
        "id": "RLMA-2024-04728",
        "modified_time": "2024-06-25T13:41:55Z",
        "versions": [
          "1.0.0"
        ]
      }
    ]
  }
}
